Workbook

Sheet Concrete materials
A1: CONCRETE
A2: Concrete quantity | B2: 1
A3: Concrete quantity after bulking | B3: =B2*1.54 -> 1.54 | G3: Work to do
A4: Concrete mix | B4: 1 | C4: 1 | D4: 1.5 | F4: 1 | G4: Insuarance of a project
A6: CEMENT
A7: Density of Cement | B7: 1440
A8: Quantity of cement required (m3) | B8: =((B4/SUM(B4:D4))*B3) -> 0.44
A9: Cement bags required | B9: =(B8*B7)/50 -> 12.672
A10: Wastage 5% | B10: =B9*1.05 -> 13.3056
A11: Cement bag cost | B11: 47000
A12: Transport cost | B12: 200000
A13: Number of bags carried | B13: 100
A14: Transport per bag | B14: =B12/B13 -> 2000
A15: Loading and offloading | B15: 1000
A16: Total cost per bag | B16: =B14+B11+B15 -> 50000
A17: Total cost cement | B17: =B16*B10 -> 665280
A19: SAND
A20: Density of Sand | B20: 1600
A21: Quantity of sand required (m3) | B21: =((C4/SUM(B4:D4))*B3) -> 0.44
A22: Quantity of sand required (tonnes) | B22: =B21*B20/1000 -> 0.704
A23: Add Material wastage 5% | B23: =B22*1.05 -> 0.7392
A24: Cost of sand | B24: 200000
A25: Transport cost | B25: 80000
A26: Quantity carried by transportation (tonnes) | B26: 2.5
A27: Total cost per ton | B27: =(B24+B25)/B26 -> 112000
A28: Total cost sand | B28: =B27*B23 -> 82790.4
A30: AGGREGATES
A31: Density of Aggregates | B31: 1500
A32: Quantity of aggregates required (m3) | B32: =((D4/SUM(B4:D4))*B3) -> 0.66
A33: Quantity of sand required (tonnes) | B33: =B32*B31/1000 -> 0.99
A34: Add Material wastage 5% | B34: =B33*1.05 -> 1.0395
A35: Cost of aggregates | B35: 250000
A36: Transport cost | B36: 100000
A37: Quantity carried by transportation (tonnes) | B37: 2.5
A38: Total cost per ton | B38: =(B35+B36)/B37 -> 140000
A39: Total cost aggregates | B39: =B38*B34 -> 145530
A41: LABOUR COSTS
A42: Number of helpers deployed | B42: 2
A43: Skilled worker | B43: ='Built up labour rate'!F15 -> 30669.643
A44: semi-skilled | B44: ='Built up labour rate'!B15 -> 15334.821
...

Sheet Insurance
A1: Project data
A2: Location | B2: Kampala
A3: Contract sum | B3: 95855744
A4: Duration (months) | B4: 1.5
A5: Labour cost | B5: 19501898
A7: Contractor's All Risks (CAR)
A8: Sum insured | B8: =B3 -> 95855744
A9: Market rate % | B9: 0.3
A10: Premium | B10: =B9%*B8 -> 287567.23
A12: Third Party Liability
A13: Liability limit | B13: 1000000000
A14: Market rate % | B14: 0.5
A15: Premium | B15: =B14%*B13 -> 5000000
A17: Workmen's compensation
A18: Labour cost | B18: =B5 -> 19501898
A19: Market rate % | B19: 0.65
A20: Premium | B20: =B19%*B18 -> 126762.34
A22: Professional Indemnity
A23: Design fee portion | B23: 200000000
A24: Market rate % | B24: 2
A25: Premium | B25: =B24%*B23 -> 4000000
A27: Statutory charges
A28: Total cost | B28: =B25+B20+B15+B10 -> 9414329.6
A29: stamp duty | B29: 35000
A30: Add broker fee 10% | B30: =(B28*0.1) -> 941432.96
A31: Add admin + profit | B31: =300000 -> 300000
A32: Approximate total | B32: =SUM(B28:B31) -> 10690763
A33: Premium | B33: =B32*B4/12 -> 1336345.3
A35: Insurance % | B35: =(B33/B3)*100 -> 1.3941213

Sheet Blockwork
A1: BLOCKWORK
A2: Area to be covered | B2: 1
A3: Thickness of the wall | B3: 0.2
A4: Mortar mix | B4: 1 | C4: 3
A5: Mortar thickness | B5: 0.015
A7: BRICKS/ BLOCKS
A8: Brick/block size | B8: 0.4 | C8: 0.2 | D8: 0.2 | F8: Item | G8: Unit | H8: Quantity | I8: Rate | J8: Amount
A9: Brick/block size with mortar | B9: =B8+$B$5 -> 0.415 | C9: =C8+$B$5 -> 0.215 | D9: =D8 -> 0.2 | F9: Bricks/blocks | G9: no. | H9: =B10 -> 11.207621 | I9: =B16 -> 1500 | J9: =H9*I9 -> 16811.432
A10: No. of blocks required | B10: =B2/(B9*C9) -> 11.207621 | F10: Cement | G10: bags | H10: =B23 -> 0.150822 | I10: =B28 -> 34000 | J10: =H10*I10 -> 5127.948
A11: Cost of brick/blocks | B11: 500 | F11: Sand | G11: tonnes | H11: =B35 -> 0.0198 | I11: =B39 -> 70000 | J11: =H11*I11 -> 1386
A12: Transport | B12: 100000 | F12: Labour | H12: 1 | I12: =B47 -> 12267.857 | J12: =H12*I12 -> 12267.857
A13: Quantity carried | B13: 200 | F13: Plant 3% | J13: =1.03*SUM(J9:J12) -> 36661.034
A14: Transport per brick/bloc | B14: =B12/B13 -> 500 | F14: Profit and overheads 20% | J14: =J13*1.2 -> 43993.241
A15: Loading and offloading | B15: 500
A16: Cost per brick/block | B16: =B11+B14+B15 -> 1500
A17: Total cost of bricks/blocks | B17: =B16*B10 -> 16811.432
A19: CEMENT
A20: Density of Cement | B20: 1440
A21: Quantity of cement required (m3) | B21: =((B4/SUM(B4:C4))*B2*B5)*1.33 -> 0.0049875
A22: Cement bags required | B22: =(B21*B20)/50 -> 0.14364
A23: Add material wastage 5% | B23: =B22*1.05 -> 0.150822
A24: Cement bag cost | B24: 32000
A25: Transport cost | B25: 200000
A26: Number of bags carried | B26: 100
A27: Transport per bag | B27: =B25/B26 -> 2000
A28: Total cost per bag | B28: =B27+B24 -> 34000
A29: Total cost cement | B29: =B28*B23 -> 5127.948
A31: SAND
A32: Density of Sand | B32: 1600
A33: Quantity of sand required (m3) | B33: =((C4/SUM(B4:C4))*B2*B5) -> 0.01125
A34: Quantity of sand required (tonnes) | B34: =B33*B32/1000 -> 0.018
A35: Add Material wastage 10% | B35: =B34*1.1 -> 0.0198
A36: Cost of sand | B36: 200000
A37: Transport cost | B37: 80000
A38: Quantity carried by transportation (tonnes) | B38: 4
A39: Total cost per ton | B39: =(B36+B37)/B38 -> 70000
A40: Total cost sand | B40: =B39*B35 -> 1386
A42: LABOUR COSTS
A43: Number of mansons deployed | B43: 2
A44: Skilled worker | B44: ='Built up labour rate'!F15 -> 30669.643
...

Sheet Built up labour rate
A1: Labour
A2: Working hours | B2: 8
A3: Days | B3: 5
A5: Semi-skilled labour | E5: Skilled labour
A6: Basic pay per day | B6: 15000 | E6: Basic pay per day | F6: 30000
A7: Basic pay per hour | B7: =B6/B2 -> 1875 | E7: Basic pay per hour | F7: =F6/B2 -> 3750
A8: Basic pay per week | B8: =B7*B2*B3 -> 75000 | E8: Basic pay per week | F8: =F7*B2*B3 -> 150000
A9: Add NSSF (%) | B9: 7.5 | C9: Monthly | E9: Add NSSF (%) | F9: 7.5 | G9: Monthly
A10: Third party assurance % | B10: 2.5 | C10: Monthly | E10: Third party assurance % | F10: 2.5 | G10: Monthly
A11: Guaranteed time % | B11: 2 | C11: Monthly | E11: Guaranteed time % | F11: 2 | G11: Monthly
A12: Sick benefit % | B12: 0.5 | C12: Monthly | E12: Sick benefit % | F12: 0.5 | G12: Monthly
A13: Weekly percentage % | B13: =SUM(B9:B12)/4 -> 3.125 | E13: Weekly percentage % | F13: =SUM(F9:F12)/4 -> 3.125
A14: Total cost allowances | B14: =B13%*B8 -> 2343.75 | E14: Total cost allowances | F14: =F13%*F8 -> 4687.5
A15: Total cost per day | B15: =B6+B14/7 -> 15334.821 | E15: Total cost per day | F15: =F6+F14/7 -> 30669.643
A17: Un-skilled labour
A18: Basic pay per day | B18: 10000
A19: Basic pay per hour | B19: =B18/B2 -> 1250
A20: Basic pay per week | B20: =B19*B2*B3 -> 50000
A21: Add NSSF (%) | B21: 7.5 | C21: Monthly
A22: Third party assurance % | B22: 2.5 | C22: Monthly
A23: Guaranteed time % | B23: 2 | C23: Monthly
A24: Sick benefit % | B24: 0.5 | C24: Monthly
A25: Weekly percentage % | B25: =SUM(B21:B24)/4 -> 3.125
A26: Total cost allowances | B26: =B25%*B20 -> 1562.5
A27: Total cost per day | B27: =B18+B26/7 -> 10223.214

Sheet Concrete rate
A1: Concrete
A2: Concrete mix | B2: 1 | C2: 3 | D2: 6
A5: Cement
A6: Transport | B6: 100000 | D6: Item | E6: Unit | F6: Quantity | G6: Rate | H6: Amount
A7: Quantity carried | B7: 100 | D7: Cement | E7: bags | F7: =1.05*(B11*1.54/SUM(B2:D2)) -> 4.65696 | G7: =B13 -> 49000 | H7: =F7*G7 -> 228191.04
A8: Transport per bag | B8: =B6/B7 -> 1000 | D8: Sand | E8: tonnes | F8: =1.05*(1.54*C2/SUM(B2:D2)) -> 0.4851 | G8: =B22 -> 149333.33 | H8: =F8*G8 -> 72441.6
A9: Offloading | B9: 1000 | D9: Aggregates | E9: tonnes | F9: =1.05*(1.54*D2/SUM(B2:D2)) -> 0.9702 | G9: =B31 -> 131250 | H9: =F9*G9 -> 127338.75
A10: Density of cement Kg/m3 | B10: 1440 | D10: Labour | F10: 1 | G10: =B51 -> 12267.857 | H10: =F10*G10 -> 12267.857
A11: Number of bags per cubic meter | B11: =B10/50 -> 28.8 | D11: Plant 5% | H11: =1.05*SUM(H7:H10) -> 462251.21
A12: Cost of a cement bag | B12: 47000 | D12: Profit and overheads 20% | H12: =H11*1.2 -> 554701.45
A13: Total cost per bag | B13: =B12+B8+B9 -> 49000
A14: Total cost cement bags | B14: =B13*B11 -> 1411200
A16: Sand
A17: Transport | B17: 80000
A18: Quantity carried tons | B18: 3
A19: Quantity carried m3 | B19: =((B18*1000)/B20) -> 1.875
A20: Density of sand Kg/m3 | B20: 1600
A21: Cost of a sand | B21: 200000
A22: Total cost per cubic meter | B22: =(B21+B17)/B19 -> 149333.33
A24: Aggregates
A25: Transport | B25: 100000
A26: Quantity carried tons | B26: 4
A27: Quantity carried m3 | B27: =((B26*1000)/B28) -> 2.6666667
A28: Density of sand Kg/m3 | B28: 1500
A29: Cubic meters required | B29: =1 -> 1
A30: Cost of a sand | B30: 250000
A31: Total cost per cubic meter | B31: =(B30+B25)/B27 -> 131250
A33: Total | B33: =(B14*B2)+(B22*C2)+(B31*D2) -> 2646700
A34: Total cost per m3 (materials) | B34: =B33/SUM(B2:D2) -> 264670
A35: Add Shrinkage 54% | B35: =B34*1.54 -> 407591.8
A36: Add wastage 5% | B36: =B35*1.05 -> 427971.39
A38: Machinery (ready mixer)
A39: Renting period (per hour/day) | B39: 0
A40: Volume per hour/day | B40: 0
A41: Fuel per hour/day | B41: 0
A42: Rent price per hour/day | B42: 0
A43: Total machinery per day | B43: =SUM(B39:B42) -> 0
A45: Labour
A46: No. of un-skilled labour deployed | B46: 2
A47: No. of skilled labour deployed | B47: 1
...

Sheet Paint
A1: Cost of 1 litre for 3 coats | B1: =31600*3 -> 94800
A2: coverage per litre (square meters) | B2: 10
A3: Coverage per square meter | B3: =B1/B2 -> 9480
A5: Labour per square meter | B5: 9000

Sheet Anti-termite
A1: Termidor price | B1: 180000
A2: Termidor quantity (ml) | B2: 200
A3: Target concentration (g/L) | B3: 0.08 | C3: grams per litre
A4: Concentration of product (g/L) | B4: 96
A5: Litres of concentrate per liter of solution | B5: =(B3/B4)*1000 -> 0.83333333 | C5: ml per litre
A6: Litres of mixed solution per square meter | B6: 5
A7: ml per square meter | B7: =B5*B6 -> 4.1666667
A8: Cost per square meter | B8: =((B1/200)*B7) -> 3750

Sheet Formwork timber
A1: Unit | B1: m
A2: Size | B2: 100 | C2: 50 | D2: 4mm
A3: Quantity | B3: 1
A5: Timber cost | B5: 15000
A6: Timber size (m ) | B6: 3.6
A7: Cost per square meter | B7: =B5/B6 -> 4166.6667
A9: Labour Analysis
A10: Manson wage | B10: 30000
A11: labourer wage | B11: 10000
A12: Mansons required | B12: 1
A13: Labourers required | B13: 2
A14: Output per day (m3) | B14: 5
A15: total labour per m3 | B15: =((B10*B12)+(B11*B13))/B14 -> 10000
A17: Total cost per m3 | B17: =B7+B15 -> 14166.667
A18: Add Plant/tools 3% | B18: =B17*1.03 -> 14591.667
A19: Add material wastage 10% | B19: =B18*1.1 -> 16050.833
A20: Profit 15% | B20: =B19*1.15 -> 18458.458

Sheet Pigmented lime plaster
A1: Concrete
A2: Unit | B2: m2
A3: Mix | B3: 1 | C3: 1 | D3: 6
A4: Quantity | B4: 1
A6: Cement cost build up
A7: Cement bag cost | B7: 36000
A8: Density of cement | B8: 1600
A9: Transport | B9: 0
A10: Quantity carried (bags) | B10: 30
A11: Transport per bag | B11: =B9/B10 -> 0
A12: Total Cost of 1 bag of cement | B12: =B7+B11 -> 36000
A13: Total quantity required (m2) | B13: =(B3/SUM(B3:D3))*B4*1.5 -> 0.1875
A14: Total bags required | B14: =($B$13*$B$8/50) -> 6
A15: Total Cost of bags required | B15: =$B$14*$B$7 -> 216000 | E15: =B15+B24+B33 -> 444000.12
A17: Sand cost build up
A18: Cost of sand (traansport inclusive) | B18: 380000 | C18: considered an forward 2 tonnes
A19: Density of Sand | B19: 1600
A20: Quantity carried (tonnes) | B20: 2
A21: Total cost of a ton of Sand | B21: =(B18/B20) -> 190000
A22: Total quantity required (m3) | B22: =(D3/SUM(B3:D3))*B4 -> 0.75
A23: Total quantity required (tonnes) | B23: =B22*B19/1000 -> 1.2
A24: Total cost of sand required | B24: =B23*B21 -> 228000
A26: Lime cost build up
A27: Lime bag cost | B27: 27000
A28: Density of cement | B28: 2300
A29: Transport | B29: 100000
A30: Quantity carried (bags) | B30: 30
A31: Transport per bag | B31: =B29/B30 -> 3333.3333
A32: Total Cost of 1 bag of cement | B32: =B27+B31 -> 30333.333
A33: Total quantity required (m3) | B33: =(B3/SUM(B3:D3))*B4 -> 0.125
A34: Total bags required | B34: =($B$13*$B$8/50) -> 6
A35: Total Cost of bags required | B35: =$B$34*$B$27 -> 162000 | E35: =B35+B42+B51 -> 162001
A38: Labour Analysis
A39: Manson wage | B39: 30000
A40: labourer wage | B40: 10000
A41: Mansons required | B41: 1
A42: Labourers required | B42: 1
A43: Output per day (m3) | B43: 5
A44: total labour per m3 | B44: =((B39*B41)+(B40*B42))/B43 -> 8000 | D44: =B44*0.02*0.2 -> 32
A46: Total cost per m3 | B46: =B15+B24+B35+B44 -> 614000 | C46: =B46-8000 -> 606000
...

Sheet Natural stone (Pozzolana)
A1: Mortar mix | B1: 1 | C1: 3
A2: total mix | B2: =SUM(B1:C1) -> 4
A4: Pozzolana
A5: cost | B5: 650000
A6: density | B6: 2300
A7: Tonnes carried | B7: 2.5
A8: Volume of stones (m3) | B8: =0.05 -> 0.05
A9: Cost per ton | B9: =B5/B7 -> 260000
A10: Volume of stones tons | B10: =(B8*B6)/1000 -> 0.115
A11: Total cost of stones | B11: =B9*B10 -> 29900
A13: Cement cost build up
A14: Mortar quantity | B14: =1*0.1*0.01 -> 0.001
A15: Mortar quantity after bulking | B15: =B14*1.34 -> 0.00134
A16: Cement bag cost | B16: 36000
A17: Density of cement | B17: 1440
A18: Transport for cement | B18: 0
A19: Quantity carried (bags) | B19: 72
A20: Transport per bag | B20: =B18/B19 -> 0
A21: Total Cost of 1 bag of cement | B21: =B16+B20 -> 36000
A22: Total quantity required (m3) | B22: =(B1/B2)*B15*1.5 -> 0.0005025
A23: Total bags required | B23: =(B22*B17)/50 -> 0.014472
A24: Total Cost of bags required | B24: =B21*B23 -> 520.992
A26: Sand cost build up
A27: Cost of sand | B27: 300000 | C27: considered an elf 2.5tonnes
A28: Density of Sand | B28: 1600
A29: Quantity carried (tonnes) | B29: 2
A30: Total cost of a ton of Sand | B30: =(B27/B29) -> 150000
A31: Total quantity required (m3) | B31: =(C1/B2)*B15 -> 0.001005
A32: Total quantity required (tonnes) | B32: =B31*B28/1000 -> 0.001608
A33: Total cost of sand required | B33: =B32*B30 -> 241.2
A35: Labour Analysis
A36: Manson wage | B36: 20000
A37: labourer wage | B37: 10000
A38: Mansons required | B38: 1
A39: Labourers required | B39: 2
A40: Output per day (m2) | B40: 5
A41: total labour per m2 | B41: =((B36*B38)+(B37*B39))/B40 -> 8000
A43: Total cost per m3 | B43: =B11 -> 29900 | C43: =B43-B41 -> 21900
A44: Add Plant/tools 3% | B44: =B43*1.03 -> 30797 | C44: =C43*1.03 -> 22557
A45: Add material wastage 10% | B45: =B44*1.1 -> 33876.7 | C45: =C44*1.1 -> 24812.7
...

Sheet Hardcore
A2: Sand cost build up
A3: Cost of sand (traansport inclusive) | B3: 380000 | C3: considered an forward 2 tonnes
A4: Density of Sand | B4: 1600
A5: Quantity carried (tonnes) | B5: 2
A6: Total cost of a ton of Sand | B6: =(B3/B5) -> 190000
A7: Total quantity required (m3) | B7: 0.25
A8: Total quantity required (tonnes) | B8: =B7*B4/1000 -> 0.4
A9: Total cost of sand required | B9: =B8*B6 -> 76000 | C9: =B9*0.4 -> 30400
A11: hardcore cost build up
A12: Cost of hadcore (transport inclusive) | B12: 380000 | C12: considered an elf 2.5tonnes
A13: Density of aggregates | B13: 2100
A14: Quantity carried (tonnes) | B14: =2.5 -> 2.5
A15: Total cost of a ton of aggregates | B15: =(B12/B14) -> 152000
A16: Total quantity required (m3) | B16: 0.4
A17: Total quantity required (tonnes) | B17: =B16*B13/1000 -> 0.84
A18: Total cost of aggregates required | B18: =B17*B15 -> 127680
A20: Labour Analysis
A21: Manson wage | B21: 30000
A22: labourer wage | B22: 10000
A23: Mansons required | B23: 1
A24: Labourers required | B24: 1
A25: Output per day (m3) | B25: 5
A26: total labour per m3 | B26: =((B21*B23)+(B22*B24))/B25 -> 8000
A28: Total cost per m3 | B28: 38000 | C28: =B28-8000 -> 30000
A29: Add Plant/tools 3% | B29: =B28*1.03 -> 39140 | C29: =C28*1.03 -> 30900
A30: Add material wastage 10% | B30: =B29*1.1 -> 43054 | C30: =C29*1.1 -> 33990
A31: Profit 15% | B31: =B30*1.15 -> 49512.1 | C31: =C30*1.15 -> 39088.5

Sheet Formwork sheets
A1: Unit | B1: m2
A2: Size | B2: 1.2 | C2: 2.4 | D2: 18mm
A3: Quantity | B3: 1
A5: Timber cost | B5: 65000
A6: Timber size (m2 ) | B6: =B2*C2 -> 2.88
A7: Cost per square meter | B7: =B5/B6 -> 22569.444
A9: Labour Analysis
A10: Manson wage | B10: 20000
A11: labourer wage | B11: 10000
A12: Mansons required | B12: 1
A13: Labourers required | B13: 1
A14: Output per day (m3) | B14: 5
A15: total labour per m3 | B15: =((B10*B12)+(B11*B13))/B14 -> 6000
A17: Total cost per m3 | B17: =B7+B15 -> 28569.444
A18: Add Plant/tools 3% | B18: =B17*1.03 -> 29426.528
A19: Add material wastage 10% | B19: =B18*1.1 -> 32369.181
A20: Profit 15% | B20: =B19*1.15 -> 37224.558

Sheet BRC MESH
A1: Unit | B1: m2
A2: Size | B2: 2.44 | C2: 1.22 | D2: G-10
A3: Quantity | B3: 1
A5: Timber cost | B5: 27000
A6: brc size(m ) | B6: =B2*C2-0.5 -> 2.4768
A7: Transport per square meter | B7: 500
A8: Cost per square meter | B8: =(B5/B6)+B7 -> 11401.163
A10: Labour Analysis
A11: Manson wage | B11: 20000
A12: labourer wage | B12: 10000
A13: Mansons required | B13: 1
A14: Labourers required | B14: 2
A15: Output per day (m2) | B15: 12
A16: total labour per m3 | B16: =((B11*B13)+(B12*B14))/B15 -> 3333.3333
A18: Total cost per m3 | B18: =B8 -> 11401.163
A19: Add Plant/tools 3% | B19: =B18*1.03 -> 11743.198
A20: Add material wastage 10% | B20: =B19*1.1 -> 12917.517
A21: Profit 20% | B21: =B20*1.2 -> 15501.021

Sheet Reinforcements
A1: Unit | B1: kgs
B2: m | C2: mm
A3: Size | B3: 12 | C3: 10
A4: Quantity | B4: 1
A5: Transport costs
A6: rc cost | B6: 28000
A7: rc kgs | B7: =B3*((C3*C3)/162) -> 7.4074074
A8: Cost per square meter | B8: =B6/B7 -> 3780
A10: Labour Analysis
A11: Manson wage | B11: 30000
A12: labourer wage | B12: 10000
A13: Mansons required | B13: 1
A14: Labourers required | B14: 2
A15: Output per day (kg) | B15: 50
A16: total labour per kg | B16: =((B11*B13)+(B12*B14))/B15 -> 1000
A18: Total cost per kg | B18: =B8+B16 -> 4780
A19: Add Plant/tools 3% | B19: =B18*1.03 -> 4923.4
A20: Add material wastage 10% | B20: =B19*1.1 -> 5415.74
A21: Profit 20% | B21: =B20*1.2 -> 6498.888

Sheet Fascia board
B1: L (m)
A2: Size | B2: 5.8 | C2: 220 mm
A3: Type | B3: PVC
A4: Cost of Fascia board | B4: 52500
A5: Transport | B5: 2000
A6: Cost per m | B6: =B4/B2+B5 -> 11051.724
A8: Labour Analysis
A9: Manson wage | B9: 30000
A10: labourer wage | B10: 10000
A11: Mansons required | B11: 1
A12: Labourers required | B12: 2
A13: Output per day (m) | B13: 10
A14: total labour per m | B14: =((B9*B11)+(B10*B12))/B13 -> 5000
A16: Add Plant/tools 3% | B16: =B6+B14 -> 16051.724
A17: Add material wastage 10% | B17: =B16*1.1 -> 17656.897
A18: Profit 20% | B18: =B17*1.2 -> 21188.276

Sheet Mild steel plates
B1: L (m) | C1: W (m) | D1: TH (mm)
A2: Size | B2: 1.22 | C2: 2.44 | D2: 4
A3: Weight of plate (Kgs) | B3: =B2*C2*(D2/1000)*7850 -> 93.47152
A4: Cost per plate | B4: 285000
A5: Transport per plate | B5: 1000
A6: Cost per kg | B6: =B4/B3+B5 -> 4049.0571
A8: Labour Analysis
A9: Manson wage | B9: 30000
A10: labourer wage | B10: 10000
A11: Mansons required | B11: 1
A12: Labourers required | B12: 2
A13: Output per day (m) | B13: 50
A14: total labour per m | B14: =((B9*B11)+(B10*B12))/B13 -> 1000
A16: Add Plant/tools 3% | B16: =B6+B14 -> 5049.0571
A17: Add material wastage 10% | B17: =B16*1.1 -> 5553.9628
A18: Profit 20% | B18: =B17*1.2 -> 6664.7553

Sheet Steel Hollow sections
A1: Unit | B1: kgs
B2: length | E2: Th (mm)
A3: Size | B3: 6 | C3: 70 | D3: 70 | E3: 6
A4: Quantity | B4: 1
A5: Loading and offloading costs | B5: 1000
A6: Transport costs per kg | B6: 1000
A7: rc cost | B7: 161000
A8: rc kgs | B8: =B3*6.31 -> 37.86
A9: Cost per kg | B9: =(B7/B8)+B6+B5 -> 6252.5092
A11: Labour Analysis
A12: Manson wage | B12: 30000
A13: labourer wage | B13: 20000
A14: Mansons required | B14: 1
A15: Labourers required | B15: 2
A16: Output per day (kg) | B16: 50
A17: total labour per kg | B17: =((B12*B14)+(B13*B15))/B16 -> 1400
A19: Total cost per kg | B19: =B9+B17 -> 7652.5092
A20: Add Plant/tools 3% | B20: =B19*1.03 -> 7882.0845
A21: Add material wastage 10% | B21: =B20*1.1 -> 8670.293
A22: Profit 20% | B22: =B21*1.2 -> 10404.352

Sheet Stone plinth wall
A1: Mix | B1: 1 | C1: 4
A2: Volume required | B2: 1
A3: Mortar % | B3: 0.3
A4: Stones % | B4: 0.7
A6: Cement
A7: Price | B7: 32000
A8: Density | B8: 1440
A9: Transport | B9: 100000 | C9: Considered a 4 tonne truck
A10: Quantity carried | B10: 100
A11: Transport per bag | B11: =B9/B10 -> 1000
A12: Total cost per bag | B12: =B11+B7 -> 33000
A13: Quantity required | B13: =(B1/SUM(B1:C1))*B3*B2 -> 0.06
A14: Bags required | B14: =B13*B8/50 -> 1.728
A15: Total cost cement | B15: =B14*B12 -> 57024
A17: Sand
A18: Price (transport inclusive) | B18: 250000
A19: Density | B19: 1600
A20: Quantity carried (tonnes) | B20: 4
A21: Cost per ton of sand | B21: =B18/B20 -> 62500
A22: Quantity required (cm) | B22: =(C1/SUM(B1:C1))*B3*B2 -> 0.24
A23: Quantity required tons | B23: =B22*B19/1000 -> 0.384
A24: Total cost of sand | B24: =B23*B21 -> 24000
A26: Hardcore
A27: Price (transport inclusive) | B27: 300000
A28: Density | B28: 1640
A29: Quantity carried (tonnes) | B29: 4
A30: Cost per ton of sand | B30: =B27/B29 -> 75000
A31: Quantity required (cm) | B31: =B4*B2 -> 0.7
A32: Quantity required tons | B32: =B31*B28/1000 -> 1.148
A33: Total cost of sand | B33: =B32*B30 -> 86100
A35: Labour Analysis
A36: Manson wage | B36: 30000
A37: labourer wage | B37: 10000
A38: Mansons required | B38: 1
A39: Labourers required | B39: 2
A40: Output per day (cm) | B40: 2
A41: total labour per (cm) | B41: =((B36*B38)+(B37*B39))/B40 -> 25000
A43: Total cost per kg | B43: =B33+B41+B24++B15 -> 192124
A44: Add Plant/tools 3% | B44: =B43*1.03 -> 197887.72
A45: Add material wastage 10% | B45: =B44*1.1 -> 217676.49
...

Sheet Excavator rates
A1: Excavator earthwork rate
A2: size of bucket | B2: 0.5
A3: number of bucket | B3: 1
A4: Work rate (per minute) | B4: 3.5
A5: Working hours | B5: 8
A6: Cycles | B6: =B4*60*B5 -> 1680
A7: Buckling factor | B7: 1.35
A8: Efficiency | B8: 0.8
A9: productivity of excavator | B9: =(B8*B2*B3*B6)/B7 -> 497.77778 | C9: cubic meters per day
A10: excavator hire price (day) | B10: 1200000
A11: Fuel consumption (litres) | B11: 120
A12: Fuel (litre) | B12: 5000
A13: Operator (day) | B13: 150000
A14: Labourer (day) | B14: 50000
A16: Calculations
A17: Items | B17: cost per m3
A18: Excavator | B18: =B10/B9 -> 2410.7143
A19: Fuel | B19: =(B12*B11)/B9 -> 1205.3571
A20: Operator | B20: =B13/B9 -> 301.33929
A21: Labourer | B21: =B14/B9 -> 100.44643
A23: Total cost per m3 | B23: =SUM(B18:B21) -> 4017.8571
A24: Add profit 20% | B24: =B23*1.22 -> 4901.7857

Sheet Plastering
A1: Plastering
A2: Unit | B2: m2
A3: Area to be covered | B3: 1
A4: Plaster thickness | B4: 0.02
A5: Mortar mix | B5: 1 | C5: 4
A6: total mix | B6: =SUM(B5:C5) -> 5
A8: Cement cost build up
A9: Plaster quantity | B9: =B3*B4 -> 0.02
A10: Plaster quantity after bulking | B10: =B9*1.34 -> 0.0268
A11: Cement bag cost | B11: 36000
A12: Density of cement | B12: 1440
A13: Transport for cement | B13: 200000 | C13: considered for an elf 2.5tonnes
A14: Quantity carried (bags) | B14: 100
A15: Transport per bag | B15: =B13/B14 -> 2000
A16: Total Cost of 1 bag of cement | B16: =B11+B15 -> 38000
A17: Total quantity required (m3) | B17: =(B5/B6)*B10 -> 0.00536
A18: Total bags required | B18: =(B17*B12)/50 -> 0.154368
A19: Add allowance for binder 20% | B19: =B18*1.2 -> 0.1852416
A20: Wastage 5% | B20: =B19*1.05 -> 0.19450368
A21: Total Cost of bags required | B21: =B16*B20 -> 7391.1398
A23: Sand cost build up
A24: Cost of sand | B24: 380000 | C24: considered an elf 2 tonnes
A25: Density of Sand | B25: 1600
A26: Quantity carried (tonnes) | B26: 2
A27: Total cost of a ton of Sand | B27: =(B24/B26) -> 190000
A28: Total quantity required (m3) | B28: =(C5/B6)*B10 -> 0.02144
A29: Total quantity required (tonnes) | B29: =B28*B25/1000 -> 0.034304
A30: Add wastage 10% | B30: =1.1*B29 -> 0.0377344
A31: Total cost of sand required | B31: =B30*B27 -> 7169.536
A33: Labour Analysis
A34: Manson wage | B34: 10000
A35: labourer wage | B35: 30000
A36: Mansons required | B36: 1
A37: Labourers required | B37: 1
A38: Output per day (m3) | B38: 5
A39: total labour per m3 | B39: =((B34*B36)+(B35*B37))/B38 -> 8000
A41: Total cost per m3 | B41: =B21+B31+B39 -> 22560.676
A42: Add Plant/tools 3% | B42: =B41*1.03 -> 23237.496
A43: Add material wastage 10% | B43: =B42*1.1 -> 25561.246
A44: Profit 15% | B44: =1.15*B43 -> 29395.433

Sheet General rates
A1: Item price | B1: 5000
A2: Transport and delivery | B2: 1000
A3: Total cost of item | B3: =B1+B2 -> 6000
A4: Size | B4: 6
A5: Total cost per square meter | B5: =B3/(B4) -> 1000
A7: Labour Analysis
A8: Manson wage | B8: 20000
A9: labourer wage | B9: 10000
A10: Mansons required | B10: 1
A11: Labourers required | B11: 2
A12: Output per day (m3) | B12: 5
A13: total labour per m3 | B13: =((B8*B10)+(B9*B11))/B12 -> 8000
A15: Total cost | B15: =B13+B5 -> 9000
A16: Add Plant/tools 3% | B16: =B15*1.03 -> 9270
A17: Add material wastage 10% | B17: =B16*1.1 -> 10197
A18: Profit 15% | B18: =B17*1.15 -> 11726.55
A19: Add VAT 18% | B19: =B18*1.18 -> 13837.329

Sheet Sheet1
A1: Concrete
A2: Unit | B2: m2
A3: Mix | B3: 1 | C3: 1 | D3: 6
A4: Quantity | B4: 1
A5: Quantity after bulking | B5: =B4*1.34 -> 1.34
A7: Cement cost build up
A8: Cement bag cost | B8: 36000
A9: Density of cement | B9: 1600
A10: Transport | B10: 0
A11: Quantity carried (bags) | B11: 30
A12: Transport per bag | B12: =B10/B11 -> 0
A13: Total Cost of 1 bag of cement | B13: =B8+B12 -> 36000
A14: Total quantity required (m2) | B14: =(B3/SUM(B3:D3))*B5 -> 0.1675
A15: Total bags required | B15: =($B$14*$B$9/50) -> 5.36
A16: Total Cost of bags required | B16: =$B$15*$B$8 -> 192960 | E16: =B16+B25+B34 -> 498480.17
A18: Sand cost build up
A19: Cost of sand (traansport inclusive) | B19: 380000 | C19: considered an forward 2 tonnes
A20: Density of Sand | B20: 1600
A21: Quantity carried (tonnes) | B21: 2
A22: Total cost of a ton of Sand | B22: =(B19/B21) -> 190000
A23: Total quantity required (m3) | B23: =(D3/SUM(B3:D3))*B5 -> 1.005
A24: Total quantity required (tonnes) | B24: =B23*B20/1000 -> 1.608
A25: Total cost of sand required | B25: =B24*B22 -> 305520
A27: Lime cost build up
A28: Lime bag cost | B28: 27000
A29: Density of cement | B29: 2300
A30: Transport | B30: 100000
A31: Quantity carried (bags) | B31: 30
A32: Transport per bag | B32: =B30/B31 -> 3333.3333
A33: Total Cost of 1 bag of cement | B33: =B28+B32 -> 30333.333
A34: Total quantity required (m3) | B34: =(B3/SUM(B3:D3))*B5 -> 0.1675
A35: Total bags required | B35: =($B$14*$B$9/50) -> 5.36
A36: Total Cost of bags required | B36: =$B$35*$B$28 -> 144720 | E36: =B36+B43+B52 -> 144721
A39: Labour Analysis
A40: Manson wage | B40: 30000
A41: labourer wage | B41: 10000
A42: Mansons required | B42: 1
A43: Labourers required | B43: 1
A44: Output per day (m3) | B44: 5
A45: total labour per m3 | B45: =((B40*B42)+(B41*B43))/B44 -> 8000 | D45: =B45*0.02*0.2 -> 32
...

Sheet Rafters
A1: Size | B1: 40 | C1: 100
A2: Type | B2: Eucalyptus
A3: Length (m) | B3: 3.6
A5: Cost of rafter | B5: 15000
A6: Transport of rafter | B6: 100000
A7: total number of rafters carried | B7: 200
A8: Transport per rafter | B8: =B6/B7 -> 500
A9: Loading and offloading | B9: 1000
A10: Total cost per meter | B10: =(B5/B3)+B8+B9 -> 5666.6667
A13: Labour Analysis
A14: Manson wage | B14: 30000
A15: labourer wage | B15: 15000
A16: Mansons required | B16: 1
A17: Labourers required | B17: 2
A18: Output per day (m) | B18: 5
A19: total labour per m | B19: =((B14*B16)+(B15*B17))/B18 -> 12000
A21: Total cost per m | B21: =B10+B19 -> 17666.667
A22: Add Plant/tools 3% | B22: =B21*1.03 -> 18196.667
A23: Add material wastage 10% | B23: =B22*1.1 -> 20016.333
A24: Profit 15% | B24: =1.15*B23 -> 23018.783

Sheet Iron sheets
A1: Gauge | B1: 26
A2: Size | B2: 5 | C2: 0.7
A3: Cost per sheet | B3: 126250
A4: Transport per square meter | B4: 3000
A5: Cost per square meter | B5: =B3/(B2*C2)+B4 -> 39071.429
A7: Labour Analysis
A8: Manson wage | B8: 30000
A9: labourer wage | B9: 20000
A10: Mansons required | B10: 1
A11: Labourers required | B11: 4
A12: Output per day (m2) | B12: 10
A13: total labour per m2 | B13: =((B8*B10)+(B9*B11))/B12 -> 11000
A15: Total cost per m | B15: =B5+B13 -> 50071.429
A16: Add Plant/tools 5% | B16: =B15*1.03 -> 51573.571
A17: Add material wastage 10% | B17: =B16*1.1 -> 56730.929
A18: Profit 20% | B18: =1.2*B17 -> 68077.114

Sheet Finishes
A1: size | B1: 90 | C1: 20 | D1: 900
A2: Cost per square meter | B2: 67000
A3: Transport | B3: 200000
A4: Loading and offloading | B4: 50000
A5: Loading capacity of truck (sm) | B5: 200
A6: Transport per square meter | B6: =(B3+B4)/B5 -> 1250
A7: Cost per square meter | B7: =B2+B6 -> 68250
A9: Labour Analysis
A10: Manson wage | B10: 30000
A11: labourer wage | B11: 20000
A12: Mansons required | B12: 1
A13: Labourers required | B13: 2
A14: Output per day (m2) | B14: 5
A15: total labour per m2 | B15: =((B10*B12)+(B11*B13))/B14 -> 14000
A17: Total cost per m | B17: =B7+B15 -> 82250
A18: Add Plant/tools 3% | B18: =B17*1.03 -> 84717.5
A19: Add material wastage 10% | B19: =B18*1.1 -> 93189.25
